{"error": {"type": "<class 'syscalls.CreateBlobError'>", "value": "", "traceback": ["  File \"/bin/runtime-workload.py\", line 26, in <module>\n    response = app.handle(json.loads(request.payload), sc)\n", "  File \"/srv/workload.py\", line 141, in handle\n    with syscall.create_blob() as newblob:\n", "  File \"/usr/lib/python3.10/contextlib.py\", line 135, in __enter__\n    return next(self.gen)\n", "  File \"/usr/lib/python3.10/syscalls.py\", line 345, in create_blob\n    raise CreateBlobError\n"]}, "duration": 1011337}
